
Running tests...
----------------------------------------------------------------------
....F.
======================================================================
FAIL [0.002s]: test_replace_flamarion_lucio (json_cabuloso_tests.TestKeyReplace)
----------------------------------------------------------------------
Traceback (most recent call last):
  File "/Users/fjorg1/Labs/mentoring/src/unittest/python/json_cabuloso_tests.py", line 13, in test_replace_flamarion_lucio
    self.assertTrue(result)
AssertionError: False is not true

----------------------------------------------------------------------
Ran 6 tests in 0.003s

FAILED (failures=1)

Generating XML reports...
